Workbook
Name Dilimleyici_MachineType: #N/A
Name Dilimleyici_MachineType1: #N/A
Name Dilimleyici_MaintenanceType: #N/A
Name Dilimleyici_MaintenanceType1: #N/A
Name Dilimleyici_ProductionLine: #N/A
Name Dilimleyici_ProductionLine1: #N/A
Name dinamik_arıza: OFFSET(pivot!$EN$4, 0, 0, COUNT(pivot!$EN:$EN), 1)
Name dinamik_skor: OFFSET(pivot!$EM$4, 0, 0, COUNT(pivot!$EM:$EM), 1)
Name Slicer_CriticalityLevel: #N/A
Name Slicer_MachineID: #N/A
Name Slicer_MachineType: #N/A
Name Slicer_MaintenanceType: #N/A
Name Slicer_ProductionLine: #N/A
Name Slicer_Years__InstallationDate: #N/A

Sheet data
A1: MachineID | B1: MachineType | C1: ProductionLine | D1: InstallationDate | E1: MachineAge | F1: OperatingHours | G1: LastMaintenanceDate | H1: MaintenanceType | I1: MaintenanceInterval | J1: TimeSinceLastMaintenance | K1: FailureCount | L1: TimeToFailure | M1: MTBF_hours | N1: MTTR_hours | O1: DowntimeDuration_hours | P1: DowntimeCost_USD | Q1: RepairCost_USD | R1: SparePartCost_USD | S1: TotalMaintenanceCost_USD | T1: ProductionLoss_units | U1: FailureSeverity | V1: failure prob % | W1: FailureProbability_% | X1: RiskScore | Y1: CriticalityLevel | Z1: ConditionMonitoringScore | AA1: EnergyConsumptionIncrease_% | AB1: EnvironmentalImpactScore | AC1: CostPerDowntimeHour | AD1: visibleconditionscore | AE1: visibletimetofailure | AF1: Column1 | AG1: Column2 | AH1: energyinefficienyscore | AI1: nextmaintenance
A2: MAC-0001 | B2: Robot | C2: Line A | D2: 39872 | E2: 15 | F2: 61950 | G2: 45244 | H2: Corrective | I2: 65 | J2: 103 | K2: 124 | L2: 408 | M2: 5000 | N2: 308 | O2: 38239 | P2: 114717422 | Q2: 2189631 | R2: 482545 | S2: 117389599 | T2: 118541 | U2: 6 | V2: =W2/$K$1002 -> 0.026867134 | W2: 713 | X2: 428 | Y2: Medium | Z2: 358 | AA2: 202 | AB2: 2 | AC2: =IF(O2=0,0,P2/O2) -> 3000.011 | AD2: =IF(SUBTOTAL(103,tablo1[[#This Row],[MachineID]]), tablo1[[#This Row],[ConditionMonitoringScore]], "") -> 358 | AE2: =IF(SUBTOTAL(103,tablo1[[#This Row],[MachineID]]), tablo1[[#This Row],[TimeToFailure]], "") -> 408 | AF2: xbar | AG2: =SUBTOTAL(1,pivot!BM7:BM1006) -> 267.239 | AH2: =(AA2-MIN($AA$2:$AA$1001))/(MAX($AA$2:$AA$1001)-MIN($AA$2:$AA$1001))*100 -> 60.841424 | AI2: =IF(OR(tablo1[[#This Row],[visibletimetofailure]]<5000,tablo1[[#This Row],[visibleconditionscore]]<300),"YES","NO") -> YES
A3: MAC-0002 | B3: Packaging | C3: Line D | D3: 39142 | E3: 17 | F3: 59058 | G3: 45332 | H3: Corrective | I3: 86 | J3: 15 | K3: 29 | L3: 662 | M3: 20703 | N3: 189 | O3: 5485 | P3: 16455323 | Q3: 1216215 | R3: 26821 | S3: 17939747 | T3: 26328 | U3: 4 | V3: =W3/$K$1002 -> 0.021252544 | W3: 564 | X3: 225 | Y3: Medium | Z3: 511 | AA3: 153 | AB3: 1 | AC3: =IF(O3=0,0,P3/O3) -> 3000.0589 | AD3: =IF(SUBTOTAL(103,tablo1[[#This Row],[MachineID]]), tablo1[[#This Row],[ConditionMonitoringScore]], "") -> 511 | AE3: =IF(SUBTOTAL(103,tablo1[[#This Row],[MachineID]]), tablo1[[#This Row],[TimeToFailure]], "") -> 662 | AF3: s | AG3: =SUBTOTAL(7,pivot!BM7:BM1006) -> 194.07892 | AH3: =(AA3-MIN($AA$2:$AA$1001))/(MAX($AA$2:$AA$1001)-MIN($AA$2:$AA$1001))*100 -> 44.983819 | AI3: =IF(OR(tablo1[[#This Row],[visibletimetofailure]]<5000,tablo1[[#This Row],[visibleconditionscore]]<300),"YES","NO") -> YES
A4: MAC-0003 | B4: Press | C4: Line D | D4: 40237 | E4: 14 | F4: 45374 | G4: 45294 | H4: Corrective | I4: 70 | J4: 53 | K4: 26 | L4: 875 | M4: 16813 | N4: 98 | O4: 2537 | P4: 7610107 | Q4: 171263 | R4: 92516 | S4: 7873885 | T4: 3297 | U4: 1 | V4: =W4/$K$1002 -> 0.022496043 | W4: 597 | X4: 60 | Y4: Medium | Z4: 444 | AA4: 176 | AB4: 4 | AC4: =IF(O4=0,0,P4/O4) -> 2999.648 | AD4: =IF(SUBTOTAL(103,tablo1[[#This Row],[MachineID]]), tablo1[[#This Row],[ConditionMonitoringScore]], "") -> 444 | AE4: =IF(SUBTOTAL(103,tablo1[[#This Row],[MachineID]]), tablo1[[#This Row],[TimeToFailure]], "") -> 875 | AF4: n | AG4: =SUBTOTAL(2,pivot!BM7:BM1006) -> 1000 | AH4: =(AA4-MIN($AA$2:$AA$1001))/(MAX($AA$2:$AA$1001)-MIN($AA$2:$AA$1001))*100 -> 52.427184 | AI4: =IF(OR(tablo1[[#This Row],[visibletimetofailure]]<5000,tablo1[[#This Row],[visibleconditionscore]]<300),"YES","NO") -> YES
A5: MAC-0004 | B5: Packaging | C5: Line C | D5: 38777 | E5: 18 | F5: 67122 | G5: 45285 | H5: Corrective | I5: 54 | J5: 62 | K5: 19 | L5: 555 | M5: 38362 | N5: 235 | O5: 4474 | P5: 13423367 | Q5: 2694598 | R5: 1195864 | S5: 17313829 | T5: 15660 | U5: 9 | V5: =W5/$K$1002 -> 0.025435225 | W5: 675 | X5: 607 | Y5: Medium | Z5: 429 | AA5: 186 | AB5: 5 | AC5: =IF(O5=0,0,P5/O5) -> 3000.3055 | AD5: =IF(SUBTOTAL(103,tablo1[[#This Row],[MachineID]]), tablo1[[#This Row],[ConditionMonitoringScore]], "") -> 429 | AE5: =IF(SUBTOTAL(103,tablo1[[#This Row],[MachineID]]), tablo1[[#This Row],[TimeToFailure]], "") -> 555 | AH5: =(AA5-MIN($AA$2:$AA$1001))/(MAX($AA$2:$AA$1001)-MIN($AA$2:$AA$1001))*100 -> 55.66343 | AI5: =IF(OR(tablo1[[#This Row],[visibletimetofailure]]<5000,tablo1[[#This Row],[visibleconditionscore]]<300),"YES","NO") -> YES
A6: MAC-0005 | B6: CNC | C6: Line D | D6: 40602 | E6: 13 | F6: 52832 | G6: 45282 | H6: Preventive | I6: 134 | J6: 65 | K6: 10 | L6: 4574 | M6: 50595 | N6: 101 | O6: 1013 | P6: 1012898 | Q6: 1320994 | R6: 786309 | S6: 3120201 | T6: 4355 | U6: 7 | V6: =W6/$K$1002 -> 0.020913407 | W6: 555 | X6: 388 | Y6: Low | Z6: 509 | AA6: 155 | AB6: 2 | AC6: =IF(O6=0,0,P6/O6) -> 999.89931 | AD6: =IF(SUBTOTAL(103,tablo1[[#This Row],[MachineID]]), tablo1[[#This Row],[ConditionMonitoringScore]], "") -> 509 | AE6: =IF(SUBTOTAL(103,tablo1[[#This Row],[MachineID]]), tablo1[[#This Row],[TimeToFailure]], "") -> 4574 | AF6: x | AG6: =500 -> 500 | AH6: =(AA6-MIN($AA$2:$AA$1001))/(MAX($AA$2:$AA$1001)-MIN($AA$2:$AA$1001))*100 -> 45.631068 | AI6: =IF(OR(tablo1[[#This Row],[visibletimetofailure]]<5000,tablo1[[#This Row],[visibleconditionscore]]<300),"YES","NO") -> YES
A7: MAC-0006 | B7: CNC | C7: Line D | D7: 43522 | E7: 5 | F7: 15490 | G7: 45256 | H7: Predictive | I7: 66 | J7: 91 | K7: 2 | L7: 6879 | M7: 58514 | N7: 168 | O7: 337 | P7: 1010886 | Q7: 1683595 | R7: 367793 | S7: 3062274 | T7: 741 | U7: 7 | V7: =W7/$K$1002 -> 0.012774135 | W7: 339 | X7: 237 | Y7: Medium | Z7: 712 | AA7: 104 | AB7: 3 | AC7: =IF(O7=0,0,P7/O7) -> 2999.6617 | AD7: =IF(SUBTOTAL(103,tablo1[[#This Row],[MachineID]]), tablo1[[#This Row],[ConditionMonitoringScore]], "") -> 712 | AE7: =IF(SUBTOTAL(103,tablo1[[#This Row],[MachineID]]), tablo1[[#This Row],[TimeToFailure]], "") -> 6879 | AH7: =(AA7-MIN($AA$2:$AA$1001))/(MAX($AA$2:$AA$1001)-MIN($AA$2:$AA$1001))*100 -> 29.126214 | AI7: =IF(OR(tablo1[[#This Row],[visibletimetofailure]]<5000,tablo1[[#This Row],[visibleconditionscore]]<300),"YES","NO") -> NO
A8: MAC-0007 | B8: Conveyor | C8: Line C | D8: 42792 | E8: 7 | F8: 29848 | G8: 45215 | H8: Corrective | I8: 76 | J8: 132 | K8: 9 | L8: 640 | M8: 40655 | N8: 105 | O8: 948 | P8: 2844061 | Q8: 1386561 | R8: 787048 | S8: 501767 | T8: 1422 | U8: 7 | V8: =W8/$K$1002 -> 0.019293089 | W8: 512 | X8: 359 | Y8: Medium | Z8: 541 | AA8: 160 | AB8: 3 | AC8: =IF(O8=0,0,P8/O8) -> 3000.0643 | AD8: =IF(SUBTOTAL(103,tablo1[[#This Row],[MachineID]]), tablo1[[#This Row],[ConditionMonitoringScore]], "") -> 541 | AE8: =IF(SUBTOTAL(103,tablo1[[#This Row],[MachineID]]), tablo1[[#This Row],[TimeToFailure]], "") -> 640 | AF8: t | AG8: =(AG6-AG2)/(AG3) -> 1.1993111 | AH8: =(AA8-MIN($AA$2:$AA$1001))/(MAX($AA$2:$AA$1001)-MIN($AA$2:$AA$1001))*100 -> 47.249191 | AI8: =IF(OR(tablo1[[#This Row],[visibletimetofailure]]<5000,tablo1[[#This Row],[visibleconditionscore]]<300),"YES","NO") -> YES
A9: MAC-0008 | B9: Robot | C9: Line D | D9: 40967 | E9: 12 | F9: 54948 | G9: 45255 | H9: Preventive | I9: 55 | J9: 92 | K9: 14 | L9: 3396 | M9: 40728 | N9: 140 | O9: 1958 | P9: 5874502 | Q9: 1642487 | R9: 59819 | S9: 8115179 | T9: 7049 | U9: 9 | V9: =W9/$K$1002 -> 0.023701861 | W9: 629 | X9: 566 | Y9: Medium | Z9: 405 | AA9: 192 | AB9: 4 | AC9: =IF(O9=0,0,P9/O9) -> 3000.2564 | AD9: =IF(SUBTOTAL(103,tablo1[[#This Row],[MachineID]]), tablo1[[#This Row],[ConditionMonitoringScore]], "") -> 405 | AE9: =IF(SUBTOTAL(103,tablo1[[#This Row],[MachineID]]), tablo1[[#This Row],[TimeToFailure]], "") -> 3396 | AH9: =(AA9-MIN($AA$2:$AA$1001))/(MAX($AA$2:$AA$1001)-MIN($AA$2:$AA$1001))*100 -> 57.605178 | AI9: =IF(OR(tablo1[[#This Row],[visibletimetofailure]]<5000,tablo1[[#This Row],[visibleconditionscore]]<300),"YES","NO") -> YES
A10: MAC-0009 | B10: CNC | C10: Line B | D10: 43522 | E10: 5 | F10: 21240 | G10: 45195 | H10: Predictive | I10: 133 | J10: 152 | K10: 4 | L10: 3863 | M10: 44811 | N10: 125 | O10: 500 | P10: 499994 | Q10: 156471 | R10: 99725 | S10: 75619 | T10: 2299 | U10: 1 | V10: =W10/$K$1002 -> 0.019368453 | W10: 514 | X10: 51 | Y10: Low | Z10: 522 | AA10: 173 | AB10: 2 | AC10: =IF(O10=0,0,P10/O10) -> 999.988 | AD10: =IF(SUBTOTAL(103,tablo1[[#This Row],[MachineID]]), tablo1[[#This Row],[ConditionMonitoringScore]], "") -> 522 | AE10: =IF(SUBTOTAL(103,tablo1[[#This Row],[MachineID]]), tablo1[[#This Row],[TimeToFailure]], "") -> 3863 | AF10: df | AG10: =AG4-1 -> 999 | AH10: =(AA10-MIN($AA$2:$AA$1001))/(MAX($AA$2:$AA$1001)-MIN($AA$2:$AA$1001))*100 -> 51.456311 | AI10: =IF(OR(tablo1[[#This Row],[visibletimetofailure]]<5000,tablo1[[#This Row],[visibleconditionscore]]<300),"YES","NO") -> YES
A11: MAC-0010 | B11: CNC | C11: Line D | D11: 39142 | E11: 17 | F11: 62866 | G11: 45255 | H11: Corrective | I11: 46 | J11: 92 | K11: 125 | L11: 323 | M11: 5000 | N11: 305 | O11: 38102 | P11: 114306936 | Q11: 1323933 | R11: 315868 | S11: 115946737 | T11: 49533 | U11: 3 | V11: =W11/$K$1002 -> 0.029391816 | W11: 780 | X11: 234 | Y11: Medium | Z11: 278 | AA11: 235 | AB11: 2 | AC11: =IF(O11=0,0,P11/O11) -> 3000.0246 | AD11: =IF(SUBTOTAL(103,tablo1[[#This Row],[MachineID]]), tablo1[[#This Row],[ConditionMonitoringScore]], "") -> 278 | AE11: =IF(SUBTOTAL(103,tablo1[[#This Row],[MachineID]]), tablo1[[#This Row],[TimeToFailure]], "") -> 323 | AH11: =(AA11-MIN($AA$2:$AA$1001))/(MAX($AA$2:$AA$1001)-MIN($AA$2:$AA$1001))*100 -> 71.521036 | AI11: =IF(OR(tablo1[[#This Row],[visibletimetofailure]]<5000,tablo1[[#This Row],[visibleconditionscore]]<300),"YES","NO") -> YES
A12: MAC-0011 | B12: Conveyor | C12: Line D | D12: 39142 | E12: 17 | F12: 64022 | G12: 45277 | H12: Corrective | I12: 19 | J12: 70 | K12: 128 | L12: 223 | M12: 5000 | N12: 217 | O12: 27751 | P12: 138754388 | Q12: 793658 | R12: 363345 | S12: 139911391 | T12: 77702 | U12: 3 | V12: =W12/$K$1002 -> 0.027922225 | W12: 741 | X12: 222 | Y12: High | Z12: 306 | AA12: 221 | AB12: 4 | AC12: =IF(O12=0,0,P12/O12) -> 4999.9779 | AD12: =IF(SUBTOTAL(103,tablo1[[#This Row],[MachineID]]), tablo1[[#This Row],[ConditionMonitoringScore]], "") -> 306 | AE12: =IF(SUBTOTAL(103,tablo1[[#This Row],[MachineID]]), tablo1[[#This Row],[TimeToFailure]], "") -> 223 | AF12: P(X>x) | AG12: =_xlfn.T.DIST.RT(AG8,AG10) -> 0.11534569 | AH12: =(AA12-MIN($AA$2:$AA$1001))/(MAX($AA$2:$AA$1001)-MIN($AA$2:$AA$1001))*100 -> 66.990291 | AI12: =IF(OR(tablo1[[#This Row],[visibletimetofailure]]<5000,tablo1[[#This Row],[visibleconditionscore]]<300),"YES","NO") -> YES
A13: MAC-0012 | B13: Robot | C13: Line D | D13: 42792 | E13: 7 | F13: 33901 | G13: 45308 | H13: Corrective | I13: 22 | J13: 39 | K13: 6 | L13: 7306 | M13: 55045 | N13: 130 | O13: 780 | P13: 3901038 | Q13: 2197072 | R13: 682147 | S13: 6780257 | T13: 1950 | U13: 9 | V13: =W13/$K$1002 -> 0.01183209 | W13: 314 | X13: 283 | Y13: High | Z13: 716 | AA13: 113 | AB13: 2 | AC13: =IF(O13=0,0,P13/O13) -> 5001.3308 | AD13: =IF(SUBTOTAL(103,tablo1[[#This Row],[MachineID]]), tablo1[[#This Row],[ConditionMonitoringScore]], "") -> 716 | AE13: =IF(SUBTOTAL(103,tablo1[[#This Row],[MachineID]]), tablo1[[#This Row],[TimeToFailure]], "") -> 7306 | AH13: =(AA13-MIN($AA$2:$AA$1001))/(MAX($AA$2:$AA$1001)-MIN($AA$2:$AA$1001))*100 -> 32.038835 | AI13: =IF(OR(tablo1[[#This Row],[visibletimetofailure]]<5000,tablo1[[#This Row],[visibleconditionscore]]<300),"YES","NO") -> NO
A14: MAC-0013 | B14: Press | C14: Line D | D14: 39142 | E14: 17 | F14: 51017 | G14: 45335 | H14: Preventive | I14: 44 | J14: 12 | K14: 37 | L14: 1222 | M14: 13764 | N14: 259 | O14: 9586 | P14: 47929564 | Q14: 1383384 | R14: 342609 | S14: 49655557 | T14: 19171 | U14: 3 | V14: =W14/$K$1002 -> 0.021855453 | W14: 580 | X14: 174 | Y14: High | Z14: 479 | AA14: 183 | AB14: 4 | AC14: =IF(O14=0,0,P14/O14) -> 4999.9545 | AD14: =IF(SUBTOTAL(103,tablo1[[#This Row],[MachineID]]), tablo1[[#This Row],[ConditionMonitoringScore]], "") -> 479 | AE14: =IF(SUBTOTAL(103,tablo1[[#This Row],[MachineID]]), tablo1[[#This Row],[TimeToFailure]], "") -> 1222 | AH14: =(AA14-MIN($AA$2:$AA$1001))/(MAX($AA$2:$AA$1001)-MIN($AA$2:$AA$1001))*100 -> 54.692557 | AI14: =IF(OR(tablo1[[#This Row],[visibletimetofailure]]<5000,tablo1[[#This Row],[visibleconditionscore]]<300),"YES","NO") -> YES
A15: MAC-0014 | B15: CNC | C15: Line D | D15: 43887 | E15: 4 | F15: 17780 | G15: 45235 | H15: Corrective | I15: 79 | J15: 112 | K15: 5 | L15: 5427 | M15: 35431 | N15: 102 | O15: 512 | P15: 1536939 | Q15: 338529 | R15: 144854 | S15: 2020322 | T15: 2151 | U15: 2 | V15: =W15/$K$1002 -> 0.013377044 | W15: 355 | X15: 71 | Y15: Medium | Z15: 695 | AA15: 114 | AB15: 2 | AC15: =IF(O15=0,0,P15/O15) -> 3001.834 | AD15: =IF(SUBTOTAL(103,tablo1[[#This Row],[MachineID]]), tablo1[[#This Row],[ConditionMonitoringScore]], "") -> 695 | AE15: =IF(SUBTOTAL(103,tablo1[[#This Row],[MachineID]]), tablo1[[#This Row],[TimeToFailure]], "") -> 5427 | AH15: =(AA15-MIN($AA$2:$AA$1001))/(MAX($AA$2:$AA$1001)-MIN($AA$2:$AA$1001))*100 -> 32.36246 | AI15: =IF(OR(tablo1[[#This Row],[visibletimetofailure]]<5000,tablo1[[#This Row],[visibleconditionscore]]<300),"YES","NO") -> NO
A16: MAC-0015 | B16: Robot | C16: Line A | D16: 40237 | E16: 14 | F16: 60200 | G16: 45212 | H16: Predictive | I16: 97 | J16: 135 | K16: 15 | L16: 3546 | M16: 46207 | N16: 145 | O16: 2177 | P16: 2176524 | Q16: 1659468 | R16: 560637 | S16: 4396629 | T16: 6529 | U16: 6 | V16: =W16/$K$1002 -> 0.027658452 | W16: 734 | X16: 441 | Y16: Low | Z16: 351 | AA16: 212 | AB16: 5 | AC16: =IF(O16=0,0,P16/O16) -> 999.78135 | AD16: =IF(SUBTOTAL(103,tablo1[[#This Row],[MachineID]]), tablo1[[#This Row],[ConditionMonitoringScore]], "") -> 351 | AE16: =IF(SUBTOTAL(103,tablo1[[#This Row],[MachineID]]), tablo1[[#This Row],[TimeToFailure]], "") -> 3546 | AH16: =(AA16-MIN($AA$2:$AA$1001))/(MAX($AA$2:$AA$1001)-MIN($AA$2:$AA$1001))*100 -> 64.07767 | AI16: =IF(OR(tablo1[[#This Row],[visibletimetofailure]]<5000,tablo1[[#This Row],[visibleconditionscore]]<300),"YES","NO") -> YES
A17: MAC-0016 | B17: CNC | C17: Line D | D17: 39872 | E17: 15 | F17: 59385 | G17: 45286 | H17: Predictive | I17: 42 | J17: 61 | K17: 12 | L17: 116 | M17: 45697 | N17: 314 | O17: 3766 | P17: 18828067 | Q17: 3064381 | R17: 415375 | S17: 22307822 | T17: 15062 | U17: 5 | V17: =W17/$K$1002 -> 0.021553998 | W17: 572 | X17: 286 | Y17: High | Z17: 523 | AA17: 167 | AB17: 3 | AC17: =IF(O17=0,0,P17/O17) -> 4999.4867 | AD17: =IF(SUBTOTAL(103,tablo1[[#This Row],[MachineID]]), tablo1[[#This Row],[ConditionMonitoringScore]], "") -> 523 | AE17: =IF(SUBTOTAL(103,tablo1[[#This Row],[MachineID]]), tablo1[[#This Row],[TimeToFailure]], "") -> 116 | AH17: =(AA17-MIN($AA$2:$AA$1001))/(MAX($AA$2:$AA$1001)-MIN($AA$2:$AA$1001))*100 -> 49.514563 | AI17: =IF(OR(tablo1[[#This Row],[visibletimetofailure]]<5000,tablo1[[#This Row],[visibleconditionscore]]<300),"YES","NO") -> YES
A18: MAC-0017 | B18: Conveyor | C18: Line D | D18: 44982 | E18: 1 | F18: 4139 | G18: 45187 | H18: Predictive | I18: 174 | J18: 160 | K18: 0 | L18: 12230 | M18: 63767 | N18: 211 | O18: 0 | P18: 0 | Q18: 1258074 | R18: 192025 | S18: 1450099 | T18: 0 | U18: 3 | V18: =W18/$K$1002 -> 0.014620544 | W18: 388 | X18: 117 | Y18: Low | Z18: 644 | AA18: 127 | AB18: 2 | AC18: =IF(O18=0,0,P18/O18) -> 0 | AD18: =IF(SUBTOTAL(103,tablo1[[#This Row],[MachineID]]), tablo1[[#This Row],[ConditionMonitoringScore]], "") -> 644 | AE18: =IF(SUBTOTAL(103,tablo1[[#This Row],[MachineID]]), tablo1[[#This Row],[TimeToFailure]], "") -> 12230 | AH18: =(AA18-MIN($AA$2:$AA$1001))/(MAX($AA$2:$AA$1001)-MIN($AA$2:$AA$1001))*100 -> 36.569579 | AI18: =IF(OR(tablo1[[#This Row],[visibletimetofailure]]<5000,tablo1[[#This Row],[visibleconditionscore]]<300),"YES","NO") -> NO
A19: MAC-0018 | B19: Press | C19: Line B | D19: 39142 | E19: 17 | F19: 70159 | G19: 45308 | H19: Preventive | I19: 87 | J19: 39 | K19: 35 | L19: 1990 | M19: 20067 | N19: 161 | O19: 5648 | P19: 1694338 | Q19: 1297617 | R19: 902316 | S19: 19143313 | T19: 16378 | U19: 8 | V19: =W19/$K$1002 -> 0.026339589 | W19: 699 | X19: 559 | Y19: Medium | Z19: 325 | AA19: 210 | AB19: 5 | AC19: =IF(O19=0,0,P19/O19) -> 299.98902 | AD19: =IF(SUBTOTAL(103,tablo1[[#This Row],[MachineID]]), tablo1[[#This Row],[ConditionMonitoringScore]], "") -> 325 | AE19: =IF(SUBTOTAL(103,tablo1[[#This Row],[MachineID]]), tablo1[[#This Row],[TimeToFailure]], "") -> 1990 | AH19: =(AA19-MIN($AA$2:$AA$1001))/(MAX($AA$2:$AA$1001)-MIN($AA$2:$AA$1001))*100 -> 63.430421 | AI19: =IF(OR(tablo1[[#This Row],[visibletimetofailure]]<5000,tablo1[[#This Row],[visibleconditionscore]]<300),"YES","NO") -> YES
A20: MAC-0019 | B20: CNC | C20: Line D | D20: 40237 | E20: 14 | F20: 47586 | G20: 45204 | H20: Corrective | I20: 176 | J20: 143 | K20: 55 | L20: 764 | M20: 8814 | N20: 124 | O20: 6826 | P20: 6826004 | Q20: 931006 | R20: 323301 | S20: 808031 | T20: 16382 | U20: 6 | V20: =W20/$K$1002 -> 0.029090361 | W20: 772 | X20: 463 | Y20: Low | Z20: 302 | AA20: 236 | AB20: 2 | AC20: =IF(O20=0,0,P20/O20) -> 1000.0006 | AD20: =IF(SUBTOTAL(103,tablo1[[#This Row],[MachineID]]), tablo1[[#This Row],[ConditionMonitoringScore]], "") -> 302 | AE20: =IF(SUBTOTAL(103,tablo1[[#This Row],[MachineID]]), tablo1[[#This Row],[TimeToFailure]], "") -> 764 | AH20: =(AA20-MIN($AA$2:$AA$1001))/(MAX($AA$2:$AA$1001)-MIN($AA$2:$AA$1001))*100 -> 71.84466 | AI20: =IF(OR(tablo1[[#This Row],[visibletimetofailure]]<5000,tablo1[[#This Row],[visibleconditionscore]]<300),"YES","NO") -> YES
A21: MAC-0020 | B21: Conveyor | C21: Line D | D21: 43522 | E21: 5 | F21: 19960 | G21: 45342 | H21: Predictive | I21: 42 | J21: 5 | K21: 2 | L21: 9158 | M21: 81673 | N21: 162 | O21: 324 | P21: 161898 | Q21: 956592 | R21: 364379 | S21: 2939951 | T21: 906 | U21: 3 | V21: =W21/$K$1002 -> 0.0076117266 | W21: 202 | X21: 61 | Y21: High | Z21: 797 | AA21: 69 | AB21: 4 | AC21: =IF(O21=0,0,P21/O21) -> 499.68519 | AD21: =IF(SUBTOTAL(103,tablo1[[#This Row],[MachineID]]), tablo1[[#This Row],[ConditionMonitoringScore]], "") -> 797 | AE21: =IF(SUBTOTAL(103,tablo1[[#This Row],[MachineID]]), tablo1[[#This Row],[TimeToFailure]], "") -> 9158 | AH21: =(AA21-MIN($AA$2:$AA$1001))/(MAX($AA$2:$AA$1001)-MIN($AA$2:$AA$1001))*100 -> 17.799353 | AI21: =IF(OR(tablo1[[#This Row],[visibletimetofailure]]<5000,tablo1[[#This Row],[visibleconditionscore]]<300),"YES","NO") -> NO
A22: MAC-0021 | B22: CNC | C22: Line D | D22: 38412 | E22: 19 | F22: 87913 | G22: 45230 | H22: Corrective | I22: 70 | J22: 117 | K22: 175 | L22: 157 | M22: 5000 | N22: 316 | O22: 55361 | P22: 166082186 | Q22: 809807 | R22: 290973 | S22: 167182965 | T22: 265731 | U22: 2 | V22: =W22/$K$1002 -> 0.032745497 | W22: 869 | X22: 174 | Y22: Medium | Z22: 221 | AA22: 255 | AB22: 1 | AC22: =IF(O22=0,0,P22/O22) -> 2999.9853 | AD22: =IF(SUBTOTAL(103,tablo1[[#This Row],[MachineID]]), tablo1[[#This Row],[ConditionMonitoringScore]], "") -> 221 | AE22: =IF(SUBTOTAL(103,tablo1[[#This Row],[MachineID]]), tablo1[[#This Row],[TimeToFailure]], "") -> 157 | AH22: =(AA22-MIN($AA$2:$AA$1001))/(MAX($AA$2:$AA$1001)-MIN($AA$2:$AA$1001))*100 -> 77.993528 | AI22: =IF(OR(tablo1[[#This Row],[visibletimetofailure]]<5000,tablo1[[#This Row],[visibleconditionscore]]<300),"YES","NO") -> YES
A23: MAC-0022 | B23: Packaging | C23: Line B | D23: 44252 | E23: 3 | F23: 12297 | G23: 45261 | H23: Preventive | I23: 81 | J23: 86 | K23: 2 | L23: 8436 | M23: 71938 | N23: 45 | O23: 90 | P23: 270723 | Q23: 45895 | R23: 126336 | S23: 442955 | T23: 270 | U23: 1 | V23: =W23/$K$1002 -> 0.0098726355 | W23: 262 | X23: 26 | Y23: Medium | Z23: 781 | AA23: 75 | AB23: 4 | AC23: =IF(O23=0,0,P23/O23) -> 3008.0333 | AD23: =IF(SUBTOTAL(103,tablo1[[#This Row],[MachineID]]), tablo1[[#This Row],[ConditionMonitoringScore]], "") -> 781 | AE23: =IF(SUBTOTAL(103,tablo1[[#This Row],[MachineID]]), tablo1[[#This Row],[TimeToFailure]], "") -> 8436 | AH23: =(AA23-MIN($AA$2:$AA$1001))/(MAX($AA$2:$AA$1001)-MIN($AA$2:$AA$1001))*100 -> 19.7411 | AI23: =IF(OR(tablo1[[#This Row],[visibletimetofailure]]<5000,tablo1[[#This Row],[visibleconditionscore]]<300),"YES","NO") -> NO
A24: MAC-0023 | B24: Robot | C24: Line A | D24: 43522 | E24: 5 | F24: 15110 | G24: 45247 | H24: Corrective | I24: 158 | J24: 100 | K24: 3 | L24: 7217 | M24: 41301 | N24: 61 | O24: 182 | P24: 181575 | Q24: 671855 | R24: 1008161 | S24: 1861591 | T24: 599 | U24: 7 | V24: =W24/$K$1002 -> 0.014507499 | W24: 385 | X24: 269 | Y24: Low | Z24: 650 | AA24: 111 | AB24: 2 | AC24: =IF(O24=0,0,P24/O24) -> 997.66484 | AD24: =IF(SUBTOTAL(103,tablo1[[#This Row],[MachineID]]), tablo1[[#This Row],[ConditionMonitoringScore]], "") -> 650 | AE24: =IF(SUBTOTAL(103,tablo1[[#This Row],[MachineID]]), tablo1[[#This Row],[TimeToFailure]], "") -> 7217 | AH24: =(AA24-MIN($AA$2:$AA$1001))/(MAX($AA$2:$AA$1001)-MIN($AA$2:$AA$1001))*100 -> 31.391586 | AI24: =IF(OR(tablo1[[#This Row],[visibletimetofailure]]<5000,tablo1[[#This Row],[visibleconditionscore]]<300),"YES","NO") -> NO
... A1001: MAC-1000 | B1001: CNC | C1001: Line D | D1001: 43522 | E1001: 5 | F1001: 18455 | G1001: 45303 | H1001: Predictive | I1001: 82 | J1001: 44 | K1001: 3 | L1001: 8078 | M1001: 57232 | N1001: 121 | O1001: 362 | P1001: 1084632 | Q1001: 1314121 | R1001: 1002658 | S1001: 3401412 | T1001: 397 | U1001: 9 | V1001: =W1001/$K$1002 -> 0.0098726355 | W1001: 262 | X1001: 236 | Y1001: Medium | Z1001: 762 | AA1001: 92 | AB1001: 4 | AC1001: =IF(O1001=0,0,P1001/O1001) -> 2996.221 | AD1001: =IF(SUBTOTAL(103,tablo1[[#This Row],[MachineID]]), tablo1[[#This Row],[ConditionMonitoringScore]], "") -> 762 | AE1001: =IF(SUBTOTAL(103,tablo1[[#This Row],[MachineID]]), tablo1[[#This Row],[TimeToFailure]], "") -> 8078 | AH1001: =(AA1001-MIN($AA$2:$AA$1001))/(MAX($AA$2:$AA$1001)-MIN($AA$2:$AA$1001))*100 -> 25.242718 | AI1001: =IF(OR(tablo1[[#This Row],[visibletimetofailure]]<5000,tablo1[[#This Row],[visibleconditionscore]]<300),"YES","NO") -> NO
K1002: =SUM(tablo1[FailureCount]) -> 26538 | L1002: =713/26538*100 -> 2.6867134 | V1002: =SUBTOTAL(107,tablo1[failure prob %]) -> 0.0079860017
U1003: average | V1003: =AVERAGE(V2:V1001) -> 0.018324214
U1004: std dev | V1004: =_xlfn.STDEV.S(V1:V1001) -> 0.0079860017
U1005: min | V1005: =MIN(V2:V1001) -> 0.0007536363
U1006: max | V1006: =MAX(V3:V1002) -> 0.037304997

Sheet pivot
I1: CriticalityLevel | J1: (Multiple Items)
BJ2: Years (InstallationDate) | BK2: (Tümü) | BM2: Years (InstallationDate) | BN2: (Tümü) | EI2: düzeltilcek | EJ2: pie chart | EL2: yüzdde | ET2: scatter | FA2: hipotez
A3: Count of MachineID | C3: Average of MTBF_hours | E3: Average of FailureCount | G3: Average of MachineAge | I3: Count of CriticalityLevel | L3: Row Labels | M3: Count of MachineID | P3: count of machine_id | Q3: ratio | S3: Row Labels | T3: Count of MachineID | X3: Row Labels | Y3: Sum of RiskScore | AB3: Row Labels | AC3: Average of FailureCount | AI3: Average of ConditionMonitoringScore | AK3: =AI4 -> 557.746 | AM3: label | AN3: value | AO3: color | AP3: current score | AQ3: =AK3 -> 557.746 | AU3: Average of ConditionMonitoringScore | AW3: Average of EnvironmentalImpactScore | AY3: Satır Etiketleri | AZ3: Average of EnvironmentalImpactScore | BA3: Row Labels | BB3: Average of EnvironmentalImpactScore | BD3: Satır Etiketleri | BE3: Sum of failure prob % | BG3: conditionmon | BH3: failureprob | BJ3: ProductionLine | BK3: (Tümü) | BM3: ProductionLine | BN3: (Tümü) | BP3: Satır Etiketleri | BQ3: Sum of RiskScore | BR3: mc | BS3: riskscore | BU3: countif | BX3: Satır Etiketleri | BY3: Average of EnergyConsumptionIncrease_% | CC3: avg | CD3: =data!V1003 -> 0.018324214 | CH3: Satır Etiketleri | CI3: Sum of energyinefficienyscore | CM3: Satır Etiketleri | CN3: Average of energyinefficienyscore | CO3: time since last maintanence | CP3: co2 | CS3: Toplam TotalMaintenanceCost_USD | CU3: Toplam ProductionLoss_units | CW3: Değerler | CZ3: Değerler | DC3: MachineType | DD3: Toplam TotalMaintenanceCost_USD | DH3: ProductionLine | DI3: Toplam ProductionLoss_units | DM3: Değerler | DR3: MachineID | DS3: Toplam DowntimeDuration_hours | DT3: Toplam TotalMaintenanceCost_USD | DU3: mcıd | DV3: downtie | DW3: cost | DZ3: Satır Etiketleri | EA3: Ortalama FailureCount | EC3: r | EI3: Satır Etiketleri | EJ3: Ortalama failure prob % | EL3: Satır Etiketleri | EM3: Toplam ConditionMonitoringScore | EN3: Toplam TimeToFailure | ET3: Satır Etiketleri | EU3: Ortalama failure prob % | FA3: Satır Etiketleri | FB3: Average of TimeToFailure | FC3: StdDev of TimeToFailure | FD3: Count of TimeToFailure | FF3: conf int | FG3: =FJ4 -> 0.95 | FJ3: confidenceinterval | FK3: grand mean | FL3: =FK11 -> 4912.9646 | HP3: Satır Etiketleri | HQ3: Say nextmaintenance
A4: 1000 | C4: 41087.547 | E4: 26.538 | G4: 10.065 | I4: 1000 | L4: High | M4: 202 | O4: high | P4: =VLOOKUP(O4,L3:M7,2,FALSE) -> 202 | Q4: =IFERROR(P4/M8*100,0) -> 20.2 | S4: 18000-19000 | T4: 1 | X4: MAC-0001 | Y4: 428 | Z4: =Y4 -> 428 | AB4: 1 | AC4: 0.8245614 | AD4: 1 | AE4: =GETPIVOTDATA("FailureCount",$AB$3,"MachineAge",AB4) -> 0.8245614 | AI4: 557.746 | AM4: critical | AN4: 333 | AO4: red | AP4: needle_width | AQ4: 50 | AU4: 557.746 | AW4: 3.061 | AY4: CNC | AZ4: 3.1050228 | BA4: =IF(OR(AY4="",AY4="Grand Total",AY4="(blank)"),"",AY4) -> CNC | BB4: =IFERROR(VLOOKUP(BA4,AY3:AZ9,2,FALSE),"") -> 3.1050228 | BD4: 0 | BE4: 0.037304997 | BG4: =IF(OR(BD4="",BD4="Grand Total",BD4="(blank)"),"",BD4) -> 0 | BH4: =IFERROR(VLOOKUP(BG4,$BD$3:$BE$552,2,FALSE),"") -> 0.037304997 | BJ4: MachineID | BK4: (Tümü) | BM4: MachineType | BN4: (Tümü) | BP4: MAC-0001 | BQ4: 428 | BR4: =IF(OR(BP4="",BP4="Genel Toplam",BP4="(blank)"),"",BP4) -> MAC-0001 | BS4: =IFERROR(VLOOKUP(BR4,$BP$3:$BQ$1004,2,FALSE),"") -> 428 | BU4: riskscore | BV4: eşikdeğeri | BX4: 2005 | BY4: 237.44444 | BZ4: =IF(OR(BX4="",BX4="Grand Total",BX4="(blank)"),"",BX4) -> 2005 | CA4: =IFERROR(VLOOKUP(BX4,$BX$3:$BY$23,2,FALSE),"") -> 237.44444 | CC4: std dev | CD4: =data!V1004 -> 0.0079860017 | CH4: 3005 | CI4: 30.744337 | CJ4: =IF(OR(CH4="",CH4="Grand Total",CH4="(blank)"),"",CH4) -> 3005 | CK4: =IFERROR(VLOOKUP(CJ4,$CH$3:$CI$983,2,FALSE),"") -> 30.744337 | CM4: 1 | CN4: 36.326861 | CO4: =IF(OR(CM4="",CM4="Grand Total",CM4="(blank)"),"",CM4) -> 1 | CP4: =IFERROR(VLOOKUP(CO4,$CM$3:$CN$983,2,FALSE),"") -> 36.326861 | CS4: 16726070620 | CU4: 16819593 | CW4: Toplam DowntimeDuration_hours | CX4: 5655357 | CZ4: Toplam RepairCost_USD | DA4: 1371689016 | DC4: Packaging | DD4: 3583629186 | DE4: =IF(OR(DC4="",DC4="Grand Total",DC4="(blank)"),"",DC4) -> Packaging | DF4: =IFERROR(VLOOKUP(DE4,$DC$4:$DD$9,2,FALSE),"") -> 3583629186 | DH4: Line D | DI4: 4664689 | DJ4: =IF(OR(DH4="",DH4="Grand Total",DH4="(blank)"),"",DH4) -> Line D | DK4: =IFERROR(VLOOKUP(DJ4,$DH$3:$DI$8,2,FALSE),"") -> 4664689 | DM4: Toplam DowntimeCost_USD | DN4: 14796571169 | DO4: =IF(OR(DM4="",DM4="Grand Total",DM4="(blank)"),"",DM4) -> Toplam DowntimeCost_USD | DP4: =IFERROR(VLOOKUP(DO4,$DM$3:$DN$6,2,FALSE),"") -> 14796571169 | DR4: MAC-0001 | DS4: 38239 | DT4: 117389599 | DU4: =IF(OR(DR4="",DR4="Genel Toplam",DR4="(blank)"),"",DR4) -> MAC-0001 | DV4: =IFERROR(VLOOKUP(DU4,$DR$3:$DT$1004,2,FALSE),"") -> 38239 | DW4: =IFERROR(VLOOKUP(DU4,$DR$3:$DT$1004,3,FALSE),"") -> 117389599 | DZ4: Corrective | EA4: 27.658462 | EC4: =CORREL(tablo1[visibleconditionscore],tablo1[visibletimetofailure])^2 -> 0.58882772 | EE4: =IF(OR(EI4="",EI4="Grand Total"),"",EI4) -> Corrective | EF4: =IFERROR(VLOOKUP(EE4,$EI:$EJ,2,FALSE),"") -> 0.018153591 | EG4: =IFERROR(VLOOKUP(EF4,$EJ:$EK,2,FALSE),"") -> 0 | EI4: Corrective | EJ4: 0.018153591 | EL4: MAC-0001 | EM4: 358 | EN4: 408 | EO4: =CORREL(dinamik_skor,dinamik_arıza)^2 -> 0.58882772 | ET4: 15 | EU4: 0.018765544 | EV4: =IF(OR(ET4="",ET4="Genel Toplam",ET4="(blank)"),"",ET4) -> 15 | EW4: =IFERROR(VLOOKUP(EV4,$ET$3:$EU$163,2,FALSE),"") -> 0.018765544 | FA4: Corrective | FB4: 4950.5446 | FC4: 4190.3476 | FD4: 325 | FF4: average | FG4: =FB4 -> 4950.5446 | FI4: alfa | FJ4: 0.95 | FK4: test result | FL4: =IF(AND(FG13>FL3,FG12<FL3), "Fail to Reject H0", "Reject H0") -> Fail to Reject H0 | HP4: NO | HQ4: 453
L5: Low | M5: 279 | O5: low | P5: =VLOOKUP(O5,L4:M8,2,FALSE) -> 279 | S5: 0-1000 | T5: 250 | X5: MAC-0002 | Y5: 225 | Z5: =Y5 -> 225 | AB5: 2 | AC5: 1.5483871 | AD5: 2 | AE5: =GETPIVOTDATA("FailureCount",$AB$3,"MachineAge",AB5) -> 1.5483871 | AM5: warning | AN5: 333 | AO5: orange | AP5: gap | AQ5: =2000-(AQ3+AQ4) -> 1392.254 | AY5: Conveyor | AZ5: 3.1095238 | BA5: =IF(OR(AY5="",AY5="Grand Total",AY5="(blank)"),"",AY5) -> Conveyor | BB5: =IFERROR(VLOOKUP(BA5,AY4:AZ10,2,FALSE),"") -> 3.1095238 | BD5: 33 | BE5: 0.037304997 | BG5: =IF(OR(BD5="",BD5="Grand Total",BD5="(blank)"),"",BD5) -> 33 | BH5: =IFERROR(VLOOKUP(BG5,$BD$3:$BE$552,2,FALSE),"") -> 0.037304997 | BJ5: MachineType | BK5: (Tümü) | BP5: MAC-0002 | BQ5: 225 | BR5: =IF(OR(BP5="",BP5="Genel Toplam",BP5="(blank)"),"",BP5) -> MAC-0002 | BS5: =IFERROR(VLOOKUP(BR5,$BP$3:$BQ$1004,2,FALSE),"") -> 225 | BT5: 0-100 | BU5: =COUNTIFS(BS:BS,"<=100") -> 227 | BV5: =data!$AG$6 -> 500 | BX5: 2006 | BY5: 218.05357 | BZ5: =IF(OR(BX5="",BX5="Grand Total",BX5="(blank)"),"",BX5) -> 2006 | CA5: =IFERROR(VLOOKUP(BX5,$BX$3:$BY$23,2,FALSE),"") -> 218.05357 | CC5: min | CD5: =data!V1005 -> 0.0007536363 | CH5: 3054 | CI5: 4.2071197 | CJ5: =IF(OR(CH5="",CH5="Grand Total",CH5="(blank)"),"",CH5) -> 3054 | CK5: =IFERROR(VLOOKUP(CJ5,$CH$3:$CI$983,2,FALSE),"") -> 4.2071197 | CM5: 2 | CN5: 30.960086 | CO5: =IF(OR(CM5="",CM5="Grand Total",CM5="(blank)"),"",CM5) -> 2 | CP5: =IFERROR(VLOOKUP(CO5,$CM$3:$CN$983,2,FALSE),"") -> 30.960086 | CW5: Toplam FailureCount | CX5: 26538 | CZ5: Toplam FailureCount | DA5: 26538 | DC5: Press | DD5: 3458211525 | DE5: =IF(OR(DC5="",DC5="Grand Total",DC5="(blank)"),"",DC5) -> Press | DF5: =IFERROR(VLOOKUP(DE5,$DC$4:$DD$9,2,FALSE),"") -> 3458211525 | DH5: Line C | DI5: 3549624 | DJ5: =IF(OR(DH5="",DH5="Grand Total",DH5="(blank)"),"",DH5) -> Line C | DK5: =IFERROR(VLOOKUP(DJ5,$DH$3:$DI$8,2,FALSE),"") -> 3549624 | DM5: Toplam RepairCost_USD | DN5: 1371689016 | DO5: =IF(OR(DM5="",DM5="Grand Total",DM5="(blank)"),"",DM5) -> Toplam RepairCost_USD | DP5: =IFERROR(VLOOKUP(DO5,$DM$3:$DN$6,2,FALSE),"") -> 1371689016 | DR5: MAC-0002 | DS5: 5485 | DT5: 17939747 | DU5: =IF(OR(DR5="",DR5="Genel Toplam",DR5="(blank)"),"",DR5) -> MAC-0002 | DV5: =IFERROR(VLOOKUP(DU5,$DR$3:$DT$1004,2,FALSE),"") -> 5485 | DW5: =IFERROR(VLOOKUP(DU5,$DR$3:$DT$1004,3,FALSE),"") -> 17939747 | DZ5: Predictive | EA5: 23.922849 | EE5: =IF(OR(EI5="",EI5="Grand Total"),"",EI5) -> Predictive | EF5: =IFERROR(VLOOKUP(EE5,$EI:$EJ,2,FALSE),"") -> 0.018007435 | EI5: Predictive | EJ5: 0.018007435 | EL5: MAC-0002 | EM5: 511 | EN5: 662 | ET5: 16 | EU5: 0.018325923 | EV5: =IF(OR(ET5="",ET5="Genel Toplam",ET5="(blank)"),"",ET5) -> 16 | EW5: =IFERROR(VLOOKUP(EV5,$ET$3:$EU$163,2,FALSE),"") -> 0.018325923 | FA5: Predictive | FB5: 4905.0178 | FC5: 4161.29 | FD5: 337 | FF5: s | FG5: =FC4 -> 4190.3476 | HP5: YES | HQ5: 547
L6: Medium | M6: 519 | O6: medium | P6: =VLOOKUP(O6,L5:M9,2,FALSE) -> 519 | S6: 1000-2000 | T6: 113 | X6: MAC-0003 | Y6: 60 | Z6: =Y6 -> 60 | AB6: 3 | AC6: 2.6181818 | AD6: 3 | AE6: =GETPIVOTDATA("FailureCount",$AB$3,"MachineAge",AB6) -> 2.6181818 | AM6: healthy | AN6: 334 | AO6: green | AY6: Packaging | AZ6: 2.9617225 | BA6: =IF(OR(AY6="",AY6="Grand Total",AY6="(blank)"),"",AY6) -> Packaging | BB6: =IFERROR(VLOOKUP(BA6,AY5:AZ11,2,FALSE),"") -> 2.9617225 | BD6: 50 | BE6: 0.037304997 | BG6: =IF(OR(BD6="",BD6="Grand Total",BD6="(blank)"),"",BD6) -> 50 | BH6: =IFERROR(VLOOKUP(BG6,$BD$3:$BE$552,2,FALSE),"") -> 0.037304997 | BM6: RiskScore | BN6: MachineID | BP6: MAC-0003 | BQ6: 60 | BR6: =IF(OR(BP6="",BP6="Genel Toplam",BP6="(blank)"),"",BP6) -> MAC-0003 | BS6: =IFERROR(VLOOKUP(BR6,$BP$3:$BQ$1004,2,FALSE),"") -> 60 | BT6: 100-200 | BU6: =COUNTIFS(BS:BS,">100",BS:BS,"<=200") -> 235 | BV6: =data!$AG$6 -> 500 | BX6: 2007 | BY6: 203.40299 | BZ6: =IF(OR(BX6="",BX6="Grand Total",BX6="(blank)"),"",BX6) -> 2007 | CA6: =IFERROR(VLOOKUP(BX6,$BX$3:$BY$23,2,FALSE),"") -> 203.40299 | CC6: max | CD6: =data!V1006 -> 0.037304997 | CH6: 3058 | CI6: 25.242718 | CJ6: =IF(OR(CH6="",CH6="Grand Total",CH6="(blank)"),"",CH6) -> 3058 | CK6: =IFERROR(VLOOKUP(CJ6,$CH$3:$CI$983,2,FALSE),"") -> 25.242718 | CM6: 3 | CN6: 22.330097 | CO6: =IF(OR(CM6="",CM6="Grand Total",CM6="(blank)"),"",CM6) -> 3 | CP6: =IFERROR(VLOOKUP(CO6,$CM$3:$CN$983,2,FALSE),"") -> 22.330097 | CW6: Toplam Downtime Hour per Failure | CX6: 213.10411 | CZ6: Toplam Average Repair Cost | DA6: 51687.731 | DC6: Robot | DD6: 3315373569 | DE6: =IF(OR(DC6="",DC6="Grand Total",DC6="(blank)"),"",DC6) -> Robot | DF6: =IFERROR(VLOOKUP(DE6,$DC$4:$DD$9,2,FALSE),"") -> 3315373569 | DH6: Line B | DI6: 4610503 | DJ6: =IF(OR(DH6="",DH6="Grand Total",DH6="(blank)"),"",DH6) -> Line B | DK6: =IFERROR(VLOOKUP(DJ6,$DH$3:$DI$8,2,FALSE),"") -> 4610503 | DM6: Toplam SparePartCost_USD | DN6: 500014357 | DO6: =IF(OR(DM6="",DM6="Grand Total",DM6="(blank)"),"",DM6) -> Toplam SparePartCost_USD | DP6: =IFERROR(VLOOKUP(DO6,$DM$3:$DN$6,2,FALSE),"") -> 500014357 | DR6: MAC-0003 | DS6: 2537 | DT6: 7873885 | DU6: =IF(OR(DR6="",DR6="Genel Toplam",DR6="(blank)"),"",DR6) -> MAC-0003 | DV6: =IFERROR(VLOOKUP(DU6,$DR$3:$DT$1004,2,FALSE),"") -> 2537 | DW6: =IFERROR(VLOOKUP(DU6,$DR$3:$DT$1004,3,FALSE),"") -> 7873885 | DZ6: Preventive | EA6: 28.068047 | EC6: =GETPIVOTDATA("FailureCount",$DZ$3) -> 26.538 | EE6: =IF(OR(EI6="",EI6="Grand Total"),"",EI6) -> Preventive | EF6: =IFERROR(VLOOKUP(EE6,$EI:$EJ,2,FALSE),"") -> 0.018804117 | EI6: Preventive | EJ6: 0.018804117 | EL6: MAC-0003 | EM6: 444 | EN6: 875 | ET6: 17 | EU6: 0.015076494 | EV6: =IF(OR(ET6="",ET6="Genel Toplam",ET6="(blank)"),"",ET6) -> 17 | EW6: =IFERROR(VLOOKUP(EV6,$ET$3:$EU$163,2,FALSE),"") -> 0.015076494 | FA6: Preventive | FB6: 4883.3314 | FC6: 4171.2034 | FD6: 338 | FF6: n | FG6: =FD4 -> 325 | FL6: =IF(FG15="Reject H0", "STATISTICAL DECISION: Reject the Null Hypothesis. The performance of the selected maintenance type is significantly different from the overall average (4912.96). This suggests that this specific strategy has a unique impact on machine reliability.", "Fail to Reject the Null Hypothesis. There is no statistically significant evidence to suggest that this maintenance type performs differently than the overall average (4912.96). Any observed difference is likely due to random sampling variation.") -> Fail to Reject the Null Hypothesis. There is no statistically significant evidence to suggest that this maintenance type performs differently than the overall average (4912.96). Any observed difference is likely due to random sampling variation.
S7: 2000-3000 | T7: 68 | X7: MAC-0004 | Y7: 607 | AB7: 4 | AC7: 3.3877551 | AD7: 4 | AE7: =GETPIVOTDATA("FailureCount",$AB$3,"MachineAge",AB7) -> 3.3877551 | AM7: invisible base | AN7: 1000 | AO7: no fill | AY7: Press | AZ7: 3.0168539 | BA7: =IF(OR(AY7="",AY7="Grand Total",AY7="(blank)"),"",AY7) -> Press | BB7: =IFERROR(VLOOKUP(BA7,AY6:AZ12,2,FALSE),"") -> 3.0168539 | BD7: 59 | BE7: 0.037304997 | BG7: =IF(OR(BD7="",BD7="Grand Total",BD7="(blank)"),"",BD7) -> 59 | BH7: =IFERROR(VLOOKUP(BG7,$BD$3:$BE$552,2,FALSE),"") -> 0.037304997 | BJ7: Count of RiskScore | BM7: 2 | BN7: MAC-0722 | BP7: MAC-0004 | BQ7: 607 | BR7: =IF(OR(BP7="",BP7="Genel Toplam",BP7="(blank)"),"",BP7) -> MAC-0004 | BS7: =IFERROR(VLOOKUP(BR7,$BP$3:$BQ$1004,2,FALSE),"") -> 607 | BT7: 200-300 | BU7: =COUNTIFS(BS:BS,">200",BS:BS,"<=300") -> 173 | BV7: =data!$AG$6 -> 500 | BX7: 2008 | BY7: 200.5283 | BZ7: =IF(OR(BX7="",BX7="Grand Total",BX7="(blank)"),"",BX7) -> 2008 | CA7: =IFERROR(VLOOKUP(BX7,$BX$3:$BY$23,2,FALSE),"") -> 200.5283 | CF7: norm dist | CH7: 3131 | CI7: 20.064725 | CJ7: =IF(OR(CH7="",CH7="Grand Total",CH7="(blank)"),"",CH7) -> 3131 | CK7: =IFERROR(VLOOKUP(CJ7,$CH$3:$CI$983,2,FALSE),"") -> 20.064725 | CM7: 4 | CN7: 31.643294 | CO7: =IF(OR(CM7="",CM7="Grand Total",CM7="(blank)"),"",CM7) -> 4 | CP7: =IFERROR(VLOOKUP(CO7,$CM$3:$CN$983,2,FALSE),"") -> 31.643294 | DC7: CNC | DD7: 3269552101 | DE7: =IF(OR(DC7="",DC7="Grand Total",DC7="(blank)"),"",DC7) -> CNC | DF7: =IFERROR(VLOOKUP(DE7,$DC$4:$DD$9,2,FALSE),"") -> 3269552101 | DH7: Line A | DI7: 3994777 | DJ7: =IF(OR(DH7="",DH7="Grand Total",DH7="(blank)"),"",DH7) -> Line A | DK7: =IFERROR(VLOOKUP(DJ7,$DH$3:$DI$8,2,FALSE),"") -> 3994777 | DR7: MAC-0004 | DS7: 4474 | DT7: 17313829 | DU7: =IF(OR(DR7="",DR7="Genel Toplam",DR7="(blank)"),"",DR7) -> MAC-0004 | DV7: =IFERROR(VLOOKUP(DU7,$DR$3:$DT$1004,2,FALSE),"") -> 4474 | DW7: =IFERROR(VLOOKUP(DU7,$DR$3:$DT$1004,3,FALSE),"") -> 17313829 | DZ7: Genel Toplam | EA7: 26.538 | EL7: MAC-0004 | EM7: 429 | EN7: 555 | ET7: 18 | EU7: 0.019952521 | EV7: =IF(OR(ET7="",ET7="Genel Toplam",ET7="(blank)"),"",ET7) -> 18 | EW7: =IFERROR(VLOOKUP(EV7,$ET$3:$EU$163,2,FALSE),"") -> 0.019952521 | FF7: df | FG7: =FG6-1 -> 324
L8: sum | M8: =SUM(M4:M7) -> 1000 | S8: 3000-4000 | T8: 64 | X8: MAC-0005 | Y8: 388 | AB8: 5 | AC8: 4.1904762 | AD8: 5 | AE8: =GETPIVOTDATA("FailureCount",$AB$3,"MachineAge",AB8) -> 4.1904762 | AY8: Robot | AZ8: 3.1086957 | BA8: =IF(OR(AY8="",AY8="Grand Total",AY8="(blank)"),"",AY8) -> Robot | BB8: =IFERROR(VLOOKUP(BA8,AY7:AZ13,2,FALSE),"") -> 3.1086957 | BD8: 85 | BE8: 0.035684679 | BG8: =IF(OR(BD8="",BD8="Grand Total",BD8="(blank)"),"",BD8) -> 85 | BH8: =IFERROR(VLOOKUP(BG8,$BD$3:$BE$552,2,FALSE),"") -> 0.035684679 | BJ8: 1000 | BM8: 3 | BN8: MAC-0438 | BP8: MAC-0005 | BQ8: 388 | BR8: =IF(OR(BP8="",BP8="Genel Toplam",BP8="(blank)"),"",BP8) -> MAC-0005 | BS8: =IFERROR(VLOOKUP(BR8,$BP$3:$BQ$1004,2,FALSE),"") -> 388 | BT8: 300-400 | BU8: =COUNTIFS(BS:BS,">300",BS:BS,"<=400") -> 126 | BV8: =data!$AG$6 -> 500 | BX8: 2009 | BY8: 198.68627 | BZ8: =IF(OR(BX8="",BX8="Grand Total",BX8="(blank)"),"",BX8) -> 2009 | CA8: =IFERROR(VLOOKUP(BX8,$BX$3:$BY$23,2,FALSE),"") -> 198.68627 | CC8: 0 | CF8: =_xlfn.NORM.DIST(CC8,$CD$3,$CD$4,FALSE) -> 3.5918436 | CH8: 3150 | CI8: 3.236246 | CJ8: =IF(OR(CH8="",CH8="Grand Total",CH8="(blank)"),"",CH8) -> 3150 | CK8: =IFERROR(VLOOKUP(CJ8,$CH$3:$CI$983,2,FALSE),"") -> 3.236246 | CM8: 5 | CN8: 24.012945 | CO8: =IF(OR(CM8="",CM8="Grand Total",CM8="(blank)"),"",CM8) -> 5 | CP8: =IFERROR(VLOOKUP(CO8,$CM$3:$CN$983,2,FALSE),"") -> 24.012945 | DC8: Conveyor | DD8: 3099304239 | DE8: =IF(OR(DC8="",DC8="Grand Total",DC8="(blank)"),"",DC8) -> Conveyor | DF8: =IFERROR(VLOOKUP(DE8,$DC$4:$DD$9,2,FALSE),"") -> 3099304239 | DH8: Genel Toplam | DI8: 16819593 | DJ8: =IF(OR(DH8="",DH8="Grand Total",DH8="(blank)"),"",DH8) -> Genel Toplam | DK8: =IFERROR(VLOOKUP(DJ8,$DH$3:$DI$8,2,FALSE),"") -> 16819593 | DR8: MAC-0005 | DS8: 1013 | DT8: 3120201 | DU8: =IF(OR(DR8="",DR8="Genel Toplam",DR8="(blank)"),"",DR8) -> MAC-0005 | DV8: =IFERROR(VLOOKUP(DU8,$DR$3:$DT$1004,2,FALSE),"") -> 1013 | DW8: =IFERROR(VLOOKUP(DU8,$DR$3:$DT$1004,3,FALSE),"") -> 3120201 | EF8: bu da pie | EL8: MAC-0005 | EM8: 509 | EN8: 4574 | ET8: 19 | EU8: 0.014938148 | EV8: =IF(OR(ET8="",ET8="Genel Toplam",ET8="(blank)"),"",ET8) -> 19 | EW8: =IFERROR(VLOOKUP(EV8,$ET$3:$EU$163,2,FALSE),"") -> 0.014938148 | FF8: alpha | FG8: =1-FJ4 -> 0.05 | FJ8: Corrective | FK8: 4950.5446
S9: 4000-5000 | T9: 52 | X9: MAC-0006 | Y9: 237 | AB9: 6 | AC9: 5.2372881 | AD9: 6 | AE9: =GETPIVOTDATA("FailureCount",$AB$3,"MachineAge",AB9) -> 5.2372881 | AY9: Genel Toplam | AZ9: 3.061 | BA9: =IF(OR(AY9="",AY9="Grand Total",AY9="(blank)"),"",AY9) -> Genel Toplam | BB9: =IFERROR(VLOOKUP(BA9,AY8:AZ14,2,FALSE),"") -> 3.061 | BD9: 87 | BE9: 0.036400633 | BG9: =IF(OR(BD9="",BD9="Grand Total",BD9="(blank)"),"",BD9) -> 87 | BH9: =IFERROR(VLOOKUP(BG9,$BD$3:$BE$552,2,FALSE),"") -> 0.036400633 | BM9: 4 | BN9: MAC-0046 | BP9: MAC-0006 | BQ9: 237 | BR9: =IF(OR(BP9="",BP9="Genel Toplam",BP9="(blank)"),"",BP9) -> MAC-0006 | BS9: =IFERROR(VLOOKUP(BR9,$BP$3:$BQ$1004,2,FALSE),"") -> 237 | BT9: 400-500 | BU9: =COUNTIFS(BS:BS,">400",BS:BS,"<=500") -> 95 | BV9: =data!$AG$6 -> 500 | BX9: 2010 | BY9: 188.54717 | BZ9: =IF(OR(BX9="",BX9="Grand Total",BX9="(blank)"),"",BX9) -> 2010 | CA9: =IFERROR(VLOOKUP(BX9,$BX$3:$BY$23,2,FALSE),"") -> 188.54717 | CC9: 0.001 | CF9: =_xlfn.NORM.DIST(CC9,$CD$3,$CD$4,FALSE) -> 4.7500074 | CH9: 3176 | CI9: 26.537217 | CJ9: =IF(OR(CH9="",CH9="Grand Total",CH9="(blank)"),"",CH9) -> 3176 | CK9: =IFERROR(VLOOKUP(CJ9,$CH$3:$CI$983,2,FALSE),"") -> 26.537217 | CM9: 6 | CN9: 35.783634 | CO9: =IF(OR(CM9="",CM9="Grand Total",CM9="(blank)"),"",CM9) -> 6 | CP9: =IFERROR(VLOOKUP(CO9,$CM$3:$CN$983,2,FALSE),"") -> 35.783634 | DC9: Genel Toplam | DD9: 16726070620 | DR9: MAC-0006 | DS9: 337 | DT9: 3062274 | DU9: =IF(OR(DR9="",DR9="Genel Toplam",DR9="(blank)"),"",DR9) -> MAC-0006 | DV9: =IFERROR(VLOOKUP(DU9,$DR$3:$DT$1004,2,FALSE),"") -> 337 | DW9: =IFERROR(VLOOKUP(DU9,$DR$3:$DT$1004,3,FALSE),"") -> 3062274 | EL9: MAC-0006 | EM9: 712 | EN9: 6879 | ET9: 20 | EU9: 0.012083302 | EV9: =IF(OR(ET9="",ET9="Genel Toplam",ET9="(blank)"),"",ET9) -> 20 | EW9: =IFERROR(VLOOKUP(EV9,$ET$3:$EU$163,2,FALSE),"") -> 0.012083302 | FF9: t-critical | FG9: =_xlfn.T.INV.2T(FG8,FG7) -> 1.9673128 | FJ9: Predictive | FK9: 4905.0178
S10: 5000-6000 | T10: 76 | X10: MAC-0007 | Y10: 359 | AB10: 7 | AC10: 6.8958333 | AD10: 7 | AE10: =GETPIVOTDATA("FailureCount",$AB$3,"MachineAge",AB10) -> 6.8958333 | BA10: =IF(OR(AY10="",AY10="Grand Total",AY10="(blank)"),"",AY10) | BB10: =IFERROR(VLOOKUP(BA10,AY9:AZ15,2,FALSE),"") | BD10: 90 | BE10: 0.073554902 | BG10: =IF(OR(BD10="",BD10="Grand Total",BD10="(blank)"),"",BD10) -> 90 | BH10: =IFERROR(VLOOKUP(BG10,$BD$3:$BE$552,2,FALSE),"") -> 0.073554902 | BM10: 6 | BN10: MAC-0399 | BP10: MAC-0007 | BQ10: 359 | BR10: =IF(OR(BP10="",BP10="Genel Toplam",BP10="(blank)"),"",BP10) -> MAC-0007 | BS10: =IFERROR(VLOOKUP(BR10,$BP$3:$BQ$1004,2,FALSE),"") -> 359 | BT10: 500-600 | BU10: =COUNTIFS(BS:BS,">500",BS:BS,"<=600") -> 67 | BV10: =data!$AG$6 -> 500 | BX10: 2011 | BY10: 171.62 | BZ10: =IF(OR(BX10="",BX10="Grand Total",BX10="(blank)"),"",BX10) -> 2011 | CA10: =IFERROR(VLOOKUP(BX10,$BX$3:$BY$23,2,FALSE),"") -> 171.62 | CC10: 0.002 | CF10: =_xlfn.NORM.DIST(CC10,$CD$3,$CD$4,FALSE) -> 6.1838861 | CH10: 3195 | CI10: 23.94822 | CJ10: =IF(OR(CH10="",CH10="Grand Total",CH10="(blank)"),"",CH10) -> 3195 | CK10: =IFERROR(VLOOKUP(CJ10,$CH$3:$CI$983,2,FALSE),"") -> 23.94822 | CM10: 7 | CN10: 31.634304 | CO10: =IF(OR(CM10="",CM10="Grand Total",CM10="(blank)"),"",CM10) -> 7 | CP10: =IFERROR(VLOOKUP(CO10,$CM$3:$CN$983,2,FALSE),"") -> 31.634304 | DR10: MAC-0007 | DS10: 948 | DT10: 501767 | DU10: =IF(OR(DR10="",DR10="Genel Toplam",DR10="(blank)"),"",DR10) -> MAC-0007 | DV10: =IFERROR(VLOOKUP(DU10,$DR$3:$DT$1004,2,FALSE),"") -> 948 | DW10: =IFERROR(VLOOKUP(DU10,$DR$3:$DT$1004,3,FALSE),"") -> 501767 | EL10: MAC-0007 | EM10: 541 | EN10: 640 | ET10: 21 | EU10: 0.016008491 | EV10: =IF(OR(ET10="",ET10="Genel Toplam",ET10="(blank)"),"",ET10) -> 21 | EW10: =IFERROR(VLOOKUP(EV10,$ET$3:$EU$163,2,FALSE),"") -> 0.016008491 | FF10: std error | FG10: =FG5/SQRT(FG6) -> 232.43866 | FJ10: Preventive | FK10: 4883.3314
S11: 6000-7000 | T11: 61 | X11: MAC-0008 | Y11: 566 | AB11: 8 | AC11: 8.3043478 | AD11: 8 | AE11: =GETPIVOTDATA("FailureCount",$AB$3,"MachineAge",AB11) -> 8.3043478 | BB11: =IFERROR(VLOOKUP(BA11,AY10:AZ16,2,FALSE),"") | BD11: 109 | BE11: 0.037003542 | BG11: =IF(OR(BD11="",BD11="Grand Total",BD11="(blank)"),"",BD11) -> 109 | BH11: =IFERROR(VLOOKUP(BG11,$BD$3:$BE$552,2,FALSE),"") -> 0.037003542 | BM11: 7 | BN11: MAC-0382 | BP11: MAC-0008 | BQ11: 566 | BR11: =IF(OR(BP11="",BP11="Genel Toplam",BP11="(blank)"),"",BP11) -> MAC-0008 | BS11: =IFERROR(VLOOKUP(BR11,$BP$3:$BQ$1004,2,FALSE),"") -> 566 | BT11: 600-700 | BU11: =COUNTIFS(BS:BS,">600",BS:BS,"<=700") -> 52 | BV11: =data!$AG$6 -> 500 | BX11: 2012 | BY11: 169.75472 | BZ11: =IF(OR(BX11="",BX11="Grand Total",BX11="(blank)"),"",BX11) -> 2012 | CA11: =IFERROR(VLOOKUP(BX11,$BX$3:$BY$23,2,FALSE),"") -> 169.75472 | CC11: 0.003 | CF11: =_xlfn.NORM.DIST(CC11,$CD$3,$CD$4,FALSE) -> 7.9253605 | CH11: 3249 | CI11: 12.944984 | CJ11: =IF(OR(CH11="",CH11="Grand Total",CH11="(blank)"),"",CH11) -> 3249 | CK11: =IFERROR(VLOOKUP(CJ11,$CH$3:$CI$983,2,FALSE),"") -> 12.944984 | CM11: 8 | CN11: 37.243797 | CO11: =IF(OR(CM11="",CM11="Grand Total",CM11="(blank)"),"",CM11) -> 8 | CP11: =IFERROR(VLOOKUP(CO11,$CM$3:$CN$983,2,FALSE),"") -> 37.243797 | DR11: MAC-0008 | DS11: 1958 | DT11: 8115179 | DU11: =IF(OR(DR11="",DR11="Genel Toplam",DR11="(blank)"),"",DR11) -> MAC-0008 | DV11: =IFERROR(VLOOKUP(DU11,$DR$3:$DT$1004,2,FALSE),"") -> 1958 | DW11: =IFERROR(VLOOKUP(DU11,$DR$3:$DT$1004,3,FALSE),"") -> 8115179 | EL11: MAC-0008 | EM11: 405 | EN11: 3396 | ET11: 22 | EU11: 0.014511686 | EV11: =IF(OR(ET11="",ET11="Genel Toplam",ET11="(blank)"),"",ET11) -> 22 | EW11: =IFERROR(VLOOKUP(EV11,$ET$3:$EU$163,2,FALSE),"") -> 0.014511686 | FF11: margin of error | FG11: =FG9*FG10 -> 457.27955 | FJ11: grand mean | FK11: =AVERAGE(FK8:FK10) -> 4912.9646
S12: 7000-8000 | T12: 65 | X12: MAC-0009 | Y12: 51 | AB12: 9 | AC12: 9.72 | AD12: 9 | AE12: =GETPIVOTDATA("FailureCount",$AB$3,"MachineAge",AB12) -> 9.72 | BB12: =IFERROR(VLOOKUP(BA12,AY11:AZ17,2,FALSE),"") | BD12: 128 | BE12: 0.036362951 | BG12: =IF(OR(BD12="",BD12="Grand Total",BD12="(blank)"),"",BD12) -> 128 | BH12: =IFERROR(VLOOKUP(BG12,$BD$3:$BE$552,2,FALSE),"") -> 0.036362951 | BM12: 9 | BN12: MAC-0631 | BP12: MAC-0009 | BQ12: 51 | BR12: =IF(OR(BP12="",BP12="Genel Toplam",BP12="(blank)"),"",BP12) -> MAC-0009 | BS12: =IFERROR(VLOOKUP(BR12,$BP$3:$BQ$1004,2,FALSE),"") -> 51 | BT12: 700-800 | BU12: =COUNTIFS(BS:BS,">700",BS:BS,"<=800") -> 19 | BV12: =data!$AG$6 -> 500 | BX12: 2013 | BY12: 160.21951 | BZ12: =IF(OR(BX12="",BX12="Grand Total",BX12="(blank)"),"",BX12) -> 2013 | CA12: =IFERROR(VLOOKUP(BX12,$BX$3:$BY$23,2,FALSE),"") -> 160.21951 | CC12: 0.004 | CF12: =_xlfn.NORM.DIST(CC12,$CD$3,$CD$4,FALSE) -> 9.9992379 | CH12: 3259 | CI12: 15.857605 | CJ12: =IF(OR(CH12="",CH12="Grand Total",CH12="(blank)"),"",CH12) -> 3259 | CK12: =IFERROR(VLOOKUP(CJ12,$CH$3:$CI$983,2,FALSE),"") -> 15.857605 | CM12: 9 | CN12: 25.026969 | CO12: =IF(OR(CM12="",CM12="Grand Total",CM12="(blank)"),"",CM12) -> 9 | CP12: =IFERROR(VLOOKUP(CO12,$CM$3:$CN$983,2,FALSE),"") -> 25.026969 | DR12: MAC-0009 | DS12: 500 | DT12: 75619 | DU12: =IF(OR(DR12="",DR12="Genel Toplam",DR12="(blank)"),"",DR12) -> MAC-0009 | DV12: =IFERROR(VLOOKUP(DU12,$DR$3:$DT$1004,2,FALSE),"") -> 500 | DW12: =IFERROR(VLOOKUP(DU12,$DR$3:$DT$1004,3,FALSE),"") -> 75619 | EL12: MAC-0009 | EM12: 522 | EN12: 3863 | ET12: 23 | EU12: 0.01224659 | EV12: =IF(OR(ET12="",ET12="Genel Toplam",ET12="(blank)"),"",ET12) -> 23 | EW12: =IFERROR(VLOOKUP(EV12,$ET$3:$EU$163,2,FALSE),"") -> 0.01224659 | FF12: lower CI | FG12: =FG4-FG11 -> 4493.2651
S13: 8000-9000 | T13: 53 | X13: MAC-0010 | Y13: 234 | AB13: 10 | AC13: 12.611111 | AD13: 10 | AE13: =GETPIVOTDATA("FailureCount",$AB$3,"MachineAge",AB13) -> 12.611111 | BD13: 129 | BE13: 0.034554224 | BG13: =IF(OR(BD13="",BD13="Grand Total",BD13="(blank)"),"",BD13) -> 129 | BH13: =IFERROR(VLOOKUP(BG13,$BD$3:$BE$552,2,FALSE),"") -> 0.034554224 | BM13: 9 | BN13: MAC-0654 | BP13: MAC-0010 | BQ13: 234 | BR13: =IF(OR(BP13="",BP13="Genel Toplam",BP13="(blank)"),"",BP13) -> MAC-0010 | BS13: =IFERROR(VLOOKUP(BR13,$BP$3:$BQ$1004,2,FALSE),"") -> 234 | BX13: 2014 | BY13: 145.5 | BZ13: =IF(OR(BX13="",BX13="Grand Total",BX13="(blank)"),"",BX13) -> 2014 | CA13: =IFERROR(VLOOKUP(BX13,$BX$3:$BY$23,2,FALSE),"") -> 145.5 | CC13: 0.005 | CF13: =_xlfn.NORM.DIST(CC13,$CD$3,$CD$4,FALSE) -> 12.419529 | CH13: 3299 | CI13: 29.449838 | CJ13: =IF(OR(CH13="",CH13="Grand Total",CH13="(blank)"),"",CH13) -> 3299 | CK13: =IFERROR(VLOOKUP(CJ13,$CH$3:$CI$983,2,FALSE),"") -> 29.449838 | CM13: 10 | CN13: 36.529126 | CO13: =IF(OR(CM13="",CM13="Grand Total",CM13="(blank)"),"",CM13) -> 10 | CP13: =IFERROR(VLOOKUP(CO13,$CM$3:$CN$983,2,FALSE),"") -> 36.529126 | DR13: MAC-0010 | DS13: 38102 | DT13: 115946737 | DU13: =IF(OR(DR13="",DR13="Genel Toplam",DR13="(blank)"),"",DR13) -> MAC-0010 | DV13: =IFERROR(VLOOKUP(DU13,$DR$3:$DT$1004,2,FALSE),"") -> 38102 | DW13: =IFERROR(VLOOKUP(DU13,$DR$3:$DT$1004,3,FALSE),"") -> 115946737 | EL13: MAC-0010 | EM13: 278 | EN13: 323 | ET13: 24 | EU13: 0.013027142 | EV13: =IF(OR(ET13="",ET13="Genel Toplam",ET13="(blank)"),"",ET13) -> 24 | EW13: =IFERROR(VLOOKUP(EV13,$ET$3:$EU$163,2,FALSE),"") -> 0.013027142 | FF13: upper cı | FG13: =FG4+FG11 -> 5407.8242 | FJ13: t stat | FK13: =(FG4-FL3)/FG10 -> 0.16167715 | FL13: avrg-grandmean/std error
S14: 9000-10000 | T14: 58 | X14: MAC-0011 | Y14: 222 | AB14: 11 | AC14: 17.585366 | AD14: 11 | AE14: =GETPIVOTDATA("FailureCount",$AB$3,"MachineAge",AB14) -> 17.585366 | BD14: 138 | BE14: 0.035873088 | BG14: =IF(OR(BD14="",BD14="Grand Total",BD14="(blank)"),"",BD14) -> 138 | BH14: =IFERROR(VLOOKUP(BG14,$BD$3:$BE$552,2,FALSE),"") -> 0.035873088 | BM14: 11 | BN14: MAC-0939 | BP14: MAC-0011 | BQ14: 222 | BR14: =IF(OR(BP14="",BP14="Genel Toplam",BP14="(blank)"),"",BP14) -> MAC-0011 | BS14: =IFERROR(VLOOKUP(BR14,$BP$3:$BQ$1004,2,FALSE),"") -> 222 | BX14: 2015 | BY14: 144.54 | BZ14: =IF(OR(BX14="",BX14="Grand Total",BX14="(blank)"),"",BX14) -> 2015 | CA14: =IFERROR(VLOOKUP(BX14,$BX$3:$BY$23,2,FALSE),"") -> 144.54 | CC14: 0.006 | CF14: =_xlfn.NORM.DIST(CC14,$CD$3,$CD$4,FALSE) -> 15.18566 | CH14: 3307 | CI14: 32.36246 | CJ14: =IF(OR(CH14="",CH14="Grand Total",CH14="(blank)"),"",CH14) -> 3307 | CK14: =IFERROR(VLOOKUP(CJ14,$CH$3:$CI$983,2,FALSE),"") -> 32.36246 | CM14: 11 | CN14: 39.967638 | CO14: =IF(OR(CM14="",CM14="Grand Total",CM14="(blank)"),"",CM14) -> 11 | CP14: =IFERROR(VLOOKUP(CO14,$CM$3:$CN$983,2,FALSE),"") -> 39.967638 | DR14: MAC-0011 | DS14: 27751 | DT14: 139911391 | DU14: =IF(OR(DR14="",DR14="Genel Toplam",DR14="(blank)"),"",DR14) -> MAC-0011 | DV14: =IFERROR(VLOOKUP(DU14,$DR$3:$DT$1004,2,FALSE),"") -> 27751 | DW14: =IFERROR(VLOOKUP(DU14,$DR$3:$DT$1004,3,FALSE),"") -> 139911391 | EL14: MAC-0011 | EM14: 306 | EN14: 223 | ET14: 25 | EU14: 0.016466953 | EV14: =IF(OR(ET14="",ET14="Genel Toplam",ET14="(blank)"),"",ET14) -> 25 | EW14: =IFERROR(VLOOKUP(EV14,$ET$3:$EU$163,2,FALSE),"") -> 0.016466953
S15: 10000-11000 | T15: 40 | X15: MAC-0012 | Y15: 283 | AB15: 12 | AC15: 17.471698 | AD15: 12 | AE15: =GETPIVOTDATA("FailureCount",$AB$3,"MachineAge",AB15) -> 17.471698 | BD15: 145 | BE15: 0.033348406 | BG15: =IF(OR(BD15="",BD15="Grand Total",BD15="(blank)"),"",BD15) -> 145 | BH15: =IFERROR(VLOOKUP(BG15,$BD$3:$BE$552,2,FALSE),"") -> 0.033348406 | BM15: 12 | BN15: MAC-0609 | BP15: MAC-0012 | BQ15: 283 | BR15: =IF(OR(BP15="",BP15="Genel Toplam",BP15="(blank)"),"",BP15) -> MAC-0012 | BS15: =IFERROR(VLOOKUP(BR15,$BP$3:$BQ$1004,2,FALSE),"") -> 283 | BX15: 2016 | BY15: 128.56522 | BZ15: =IF(OR(BX15="",BX15="Grand Total",BX15="(blank)"),"",BX15) -> 2016 | CA15: =IFERROR(VLOOKUP(BX15,$BX$3:$BY$23,2,FALSE),"") -> 128.56522 | CC15: 0.007 | CF15: =_xlfn.NORM.DIST(CC15,$CD$3,$CD$4,FALSE) -> 18.279006 | CH15: 3309 | CI15: 23.300971 | CJ15: =IF(OR(CH15="",CH15="Grand Total",CH15="(blank)"),"",CH15) -> 3309 | CK15: =IFERROR(VLOOKUP(CJ15,$CH$3:$CI$983,2,FALSE),"") -> 23.300971 | CM15: 12 | CN15: 28.02589 | CO15: =IF(OR(CM15="",CM15="Grand Total",CM15="(blank)"),"",CM15) -> 12 | CP15: =IFERROR(VLOOKUP(CO15,$CM$3:$CN$983,2,FALSE),"") -> 28.02589 | DR15: MAC-0012 | DS15: 780 | DT15: 6780257 | DU15: =IF(OR(DR15="",DR15="Genel Toplam",DR15="(blank)"),"",DR15) -> MAC-0012 | DV15: =IFERROR(VLOOKUP(DU15,$DR$3:$DT$1004,2,FALSE),"") -> 780 | DW15: =IFERROR(VLOOKUP(DU15,$DR$3:$DT$1004,3,FALSE),"") -> 6780257 | EL15: MAC-0012 | EM15: 716 | EN15: 7306 | ET15: 26 | EU15: 0.018426407 | EV15: =IF(OR(ET15="",ET15="Genel Toplam",ET15="(blank)"),"",ET15) -> 26 | EW15: =IFERROR(VLOOKUP(EV15,$ET$3:$EU$163,2,FALSE),"") -> 0.018426407 | FJ15: p value | FK15: =_xlfn.T.DIST.2T(ABS(FK13), FG7) -> 0.87166087
S16: 11000-12000 | T16: 27 | X16: MAC-0013 | Y16: 174 | AB16: 13 | AC16: 21.62 | AD16: 13 | AE16: =GETPIVOTDATA("FailureCount",$AB$3,"MachineAge",AB16) -> 21.62 | BD16: 149 | BE16: 0.034215088 | BG16: =IF(OR(BD16="",BD16="Grand Total",BD16="(blank)"),"",BD16) -> 149 | BH16: =IFERROR(VLOOKUP(BG16,$BD$3:$BE$552,2,FALSE),"") -> 0.034215088 | BM16: 13 | BN16: MAC-0392 | BP16: MAC-0013 | BQ16: 174 | BR16: =IF(OR(BP16="",BP16="Genel Toplam",BP16="(blank)"),"",BP16) -> MAC-0013 | BS16: =IFERROR(VLOOKUP(BR16,$BP$3:$BQ$1004,2,FALSE),"") -> 174 | BX16: 2017 | BY16: 123.25 | BZ16: =IF(OR(BX16="",BX16="Grand Total",BX16="(blank)"),"",BX16) -> 2017 | CA16: =IFERROR(VLOOKUP(BX16,$BX$3:$BY$23,2,FALSE),"") -> 123.25 | CC16: 0.008 | CF16: =_xlfn.NORM.DIST(CC16,$CD$3,$CD$4,FALSE) -> 21.660167 | CH16: 3370 | CI16: 37.216828 | CJ16: =IF(OR(CH16="",CH16="Grand Total",CH16="(blank)"),"",CH16) -> 3370 | CK16: =IFERROR(VLOOKUP(CJ16,$CH$3:$CI$983,2,FALSE),"") -> 37.216828 | CM16: 13 | CN16: 31.31068 | CO16: =IF(OR(CM16="",CM16="Grand Total",CM16="(blank)"),"",CM16) -> 13 | CP16: =IFERROR(VLOOKUP(CO16,$CM$3:$CN$983,2,FALSE),"") -> 31.31068 | DR16: MAC-0013 | DS16: 9586 | DT16: 49655557 | DU16: =IF(OR(DR16="",DR16="Genel Toplam",DR16="(blank)"),"",DR16) -> MAC-0013 | DV16: =IFERROR(VLOOKUP(DU16,$DR$3:$DT$1004,2,FALSE),"") -> 9586 | DW16: =IFERROR(VLOOKUP(DU16,$DR$3:$DT$1004,3,FALSE),"") -> 49655557 | EL16: MAC-0013 | EM16: 479 | EN16: 1222 | ET16: 27 | EU16: 0.019768822 | EV16: =IF(OR(ET16="",ET16="Genel Toplam",ET16="(blank)"),"",ET16) -> 27 | EW16: =IFERROR(VLOOKUP(EV16,$ET$3:$EU$163,2,FALSE),"") -> 0.019768822
S17: 12000-13000 | T17: 32 | X17: MAC-0014 | Y17: 71 | AB17: 14 | AC17: 30.679245 | AD17: 14 | AE17: =GETPIVOTDATA("FailureCount",$AB$3,"MachineAge",AB17) -> 30.679245 | BD17: 150 | BE17: 0.03508177 | BG17: =IF(OR(BD17="",BD17="Grand Total",BD17="(blank)"),"",BD17) -> 150 | BH17: =IFERROR(VLOOKUP(BG17,$BD$3:$BE$552,2,FALSE),"") -> 0.03508177 | BM17: 14 | BN17: MAC-0122 | BP17: MAC-0014 | BQ17: 71 | BR17: =IF(OR(BP17="",BP17="Genel Toplam",BP17="(blank)"),"",BP17) -> MAC-0014 | BS17: =IFERROR(VLOOKUP(BR17,$BP$3:$BQ$1004,2,FALSE),"") -> 71 | BX17: 2018 | BY17: 112.9661 | BZ17: =IF(OR(BX17="",BX17="Grand Total",BX17="(blank)"),"",BX17) -> 2018 | CA17: =IFERROR(VLOOKUP(BX17,$BX$3:$BY$23,2,FALSE),"") -> 112.9661 | CC17: 0.009 | CF17: =_xlfn.NORM.DIST(CC17,$CD$3,$CD$4,FALSE) -> 25.267448 | CH17: 3398 | CI17: 26.537217 | CJ17: =IF(OR(CH17="",CH17="Grand Total",CH17="(blank)"),"",CH17) -> 3398 | CK17: =IFERROR(VLOOKUP(CJ17,$CH$3:$CI$983,2,FALSE),"") -> 26.537217 | CM17: 14 | CN17: 24.110032 | CO17: =IF(OR(CM17="",CM17="Grand Total",CM17="(blank)"),"",CM17) -> 14 | CP17: =IFERROR(VLOOKUP(CO17,$CM$3:$CN$983,2,FALSE),"") -> 24.110032 | DR17: MAC-0014 | DS17: 512 | DT17: 2020322 | DU17: =IF(OR(DR17="",DR17="Genel Toplam",DR17="(blank)"),"",DR17) -> MAC-0014 | DV17: =IFERROR(VLOOKUP(DU17,$DR$3:$DT$1004,2,FALSE),"") -> 512 | DW17: =IFERROR(VLOOKUP(DU17,$DR$3:$DT$1004,3,FALSE),"") -> 2020322 | EL17: MAC-0014 | EM17: 695 | EN17: 5427 | ET17: 28 | EU17: 0.016589419 | EV17: =IF(OR(ET17="",ET17="Genel Toplam",ET17="(blank)"),"",ET17) -> 28 | EW17: =IFERROR(VLOOKUP(EV17,$ET$3:$EU$163,2,FALSE),"") -> 0.016589419
S18: 13000-14000 | T18: 19 | X18: MAC-0015 | Y18: 441 | AB18: 15 | AC18: 40.470588 | AD18: 15 | AE18: =GETPIVOTDATA("FailureCount",$AB$3,"MachineAge",AB18) -> 40.470588 | BD18: 157 | BE18: 0.034026679 | BG18: =IF(OR(BD18="",BD18="Grand Total",BD18="(blank)"),"",BD18) -> 157 | BH18: =IFERROR(VLOOKUP(BG18,$BD$3:$BE$552,2,FALSE),"") -> 0.034026679 | BM18: 14 | BN18: MAC-0174 | BP18: MAC-0015 | BQ18: 441 | BR18: =IF(OR(BP18="",BP18="Genel Toplam",BP18="(blank)"),"",BP18) -> MAC-0015 | BS18: =IFERROR(VLOOKUP(BR18,$BP$3:$BQ$1004,2,FALSE),"") -> 441 | BX18: 2019 | BY18: 104.40476 | BZ18: =IF(OR(BX18="",BX18="Grand Total",BX18="(blank)"),"",BX18) -> 2019 | CA18: =IFERROR(VLOOKUP(BX18,$BX$3:$BY$23,2,FALSE),"") -> 104.40476 | CC18: 0.01 | CF18: =_xlfn.NORM.DIST(CC18,$CD$3,$CD$4,FALSE) -> 29.016918 | CH18: 3437 | CI18: 45.954693 | CJ18: =IF(OR(CH18="",CH18="Grand Total",CH18="(blank)"),"",CH18) -> 3437 | CK18: =IFERROR(VLOOKUP(CJ18,$CH$3:$CI$983,2,FALSE),"") -> 45.954693 | CM18: 15 | CN18: 27.346278 | CO18: =IF(OR(CM18="",CM18="Grand Total",CM18="(blank)"),"",CM18) -> 15 | CP18: =IFERROR(VLOOKUP(CO18,$CM$3:$CN$983,2,FALSE),"") -> 27.346278 | DR18: MAC-0015 | DS18: 2177 | DT18: 4396629 | DU18: =IF(OR(DR18="",DR18="Genel Toplam",DR18="(blank)"),"",DR18) -> MAC-0015 | DV18: =IFERROR(VLOOKUP(DU18,$DR$3:$DT$1004,2,FALSE),"") -> 2177 | DW18: =IFERROR(VLOOKUP(DU18,$DR$3:$DT$1004,3,FALSE),"") -> 4396629 | EL18: MAC-0015 | EM18: 351 | EN18: 3546 | ET18: 29 | EU18: 0.016527244 | EV18: =IF(OR(ET18="",ET18="Genel Toplam",ET18="(blank)"),"",ET18) -> 29 | EW18: =IFERROR(VLOOKUP(EV18,$ET$3:$EU$163,2,FALSE),"") -> 0.016527244
S19: 14000-15000 | T19: 14 | X19: MAC-0016 | Y19: 286 | AB19: 16 | AC19: 54.433962 | AD19: 16 | AE19: =GETPIVOTDATA("FailureCount",$AB$3,"MachineAge",AB19) -> 54.433962 | BD19: 161 | BE19: 0.069409903 | BG19: =IF(OR(BD19="",BD19="Grand Total",BD19="(blank)"),"",BD19) -> 161 | BH19: =IFERROR(VLOOKUP(BG19,$BD$3:$BE$552,2,FALSE),"") -> 0.069409903 | BM19: 17 | BN19: MAC-0087 | BP19: MAC-0016 | BQ19: 286 | BR19: =IF(OR(BP19="",BP19="Genel Toplam",BP19="(blank)"),"",BP19) -> MAC-0016 | BS19: =IFERROR(VLOOKUP(BR19,$BP$3:$BQ$1004,2,FALSE),"") -> 286 | BX19: 2020 | BY19: 94.612245 | BZ19: =IF(OR(BX19="",BX19="Grand Total",BX19="(blank)"),"",BX19) -> 2020 | CA19: =IFERROR(VLOOKUP(BX19,$BX$3:$BY$23,2,FALSE),"") -> 94.612245 | CC19: 0.011 | CF19: =_xlfn.NORM.DIST(CC19,$CD$3,$CD$4,FALSE) -> 32.804358 | CH19: 3509 | CI19: 12.621359 | CJ19: =IF(OR(CH19="",CH19="Grand Total",CH19="(blank)"),"",CH19) -> 3509 | CK19: =IFERROR(VLOOKUP(CJ19,$CH$3:$CI$983,2,FALSE),"") -> 12.621359 | CM19: 16 | CN19: 27.249191 | CO19: =IF(OR(CM19="",CM19="Grand Total",CM19="(blank)"),"",CM19) -> 16 | CP19: =IFERROR(VLOOKUP(CO19,$CM$3:$CN$983,2,FALSE),"") -> 27.249191 | DR19: MAC-0016 | DS19: 3766 | DT19: 22307822 | DU19: =IF(OR(DR19="",DR19="Genel Toplam",DR19="(blank)"),"",DR19) -> MAC-0016 | DV19: =IFERROR(VLOOKUP(DU19,$DR$3:$DT$1004,2,FALSE),"") -> 3766 | DW19: =IFERROR(VLOOKUP(DU19,$DR$3:$DT$1004,3,FALSE),"") -> 22307822 | EL19: MAC-0016 | EM19: 523 | EN19: 116 | ET19: 30 | EU19: 0.01174919 | EV19: =IF(OR(ET19="",ET19="Genel Toplam",ET19="(blank)"),"",ET19) -> 30 | EW19: =IFERROR(VLOOKUP(EV19,$ET$3:$EU$163,2,FALSE),"") -> 0.01174919
